2022-04-29 06:54:32,287:DEBUG:certbot._internal.main:certbot version: 1.26.0
2022-04-29 06:54:32,288:DEBUG:certbot._internal.main:Location of certbot entry point: /usr/local/bin/certbot
2022-04-29 06:54:32,288:DEBUG:certbot._internal.main:Arguments: ['--webroot', '--webroot-path=/usr/share/nginx/html/letsencrypt', '--email', 'emixbal@gmail.com', '--agree-tos', '--no-eff-email', '-d', 'sewan-be.ddns.net']
2022-04-29 06:54:32,288:DEBUG:certbot._internal.main:Discovered plugins: PluginsRegistry(PluginEntryPoint#manual,PluginEntryPoint#null,PluginEntryPoint#standalone,PluginEntryPoint#webroot)
2022-04-29 06:54:32,299:DEBUG:certbot._internal.log:Root logging level set at 30
2022-04-29 06:54:32,300:DEBUG:certbot._internal.plugins.selection:Requested authenticator webroot and installer None
2022-04-29 06:54:32,302:DEBUG:certbot._internal.plugins.selection:Single candidate plugin: * webroot
Description: Place files in webroot directory
Interfaces: Authenticator, Plugin
Entry point: webroot = certbot._internal.plugins.webroot:Authenticator
Initialized: <certbot._internal.plugins.webroot.Authenticator object at 0x7fc288a454c0>
Prep: True
2022-04-29 06:54:32,302:DEBUG:certbot._internal.plugins.selection:Selected authenticator <certbot._internal.plugins.webroot.Authenticator object at 0x7fc288a454c0> and installer None
2022-04-29 06:54:32,303:INFO:certbot._internal.plugins.selection:Plugins selected: Authenticator webroot, Installer None
2022-04-29 06:54:32,308:DEBUG:certbot._internal.main:Picked account: <Account(RegistrationResource(body=Registration(key=None, contact=(), agreement=None, status=None, terms_of_service_agreed=None, only_return_existing=None, external_account_binding=None), uri='https://acme-v02.api.letsencrypt.org/acme/acct/520826277', new_authzr_uri=None, terms_of_service=None), 0ca433842d4e214e4bfbd621de69eb43, Meta(creation_dt=datetime.datetime(2022, 4, 29, 6, 17, 13, tzinfo=<UTC>), creation_host='7f7a020dca5f', register_to_eff=None))>
2022-04-29 06:54:32,308:DEBUG:acme.client:Sending GET request to https://acme-v02.api.letsencrypt.org/directory.
2022-04-29 06:54:32,310:DEBUG:urllib3.connectionpool:Starting new HTTPS connection (1): acme-v02.api.letsencrypt.org:443
2022-04-29 06:54:32,987:DEBUG:urllib3.connectionpool:https://acme-v02.api.letsencrypt.org:443 "GET /directory HTTP/1.1" 200 658
2022-04-29 06:54:32,987:DEBUG:acme.client:Received response:
HTTP 200
Server: nginx
Date: Fri, 29 Apr 2022 06:54:32 GMT
Content-Type: application/json
Content-Length: 658
Connection: keep-alive
Cache-Control: public, max-age=0, no-cache
X-Frame-Options: DENY
Strict-Transport-Security: max-age=604800

{
  "Bu1noSVQP-M": "https://community.letsencrypt.org/t/adding-random-entries-to-the-directory/33417",
  "keyChange": "https://acme-v02.api.letsencrypt.org/acme/key-change",
  "meta": {
    "caaIdentities": [
      "letsencrypt.org"
    ],
    "termsOfService": "https://letsencrypt.org/documents/LE-SA-v1.2-November-15-2017.pdf",
    "website": "https://letsencrypt.org"
  },
  "newAccount": "https://acme-v02.api.letsencrypt.org/acme/new-acct",
  "newNonce": "https://acme-v02.api.letsencrypt.org/acme/new-nonce",
  "newOrder": "https://acme-v02.api.letsencrypt.org/acme/new-order",
  "revokeCert": "https://acme-v02.api.letsencrypt.org/acme/revoke-cert"
}
2022-04-29 06:54:32,998:DEBUG:urllib3.connectionpool:Starting new HTTP connection (1): r3.o.lencr.org:80
2022-04-29 06:54:33,002:DEBUG:urllib3.connectionpool:http://r3.o.lencr.org:80 "POST / HTTP/1.1" 200 503
2022-04-29 06:54:33,003:DEBUG:certbot.ocsp:OCSP response for certificate /etc/letsencrypt/archive/sewan-be.ddns.net/cert1.pem is signed by the certificate's issuer.
2022-04-29 06:54:33,003:DEBUG:certbot.ocsp:OCSP certificate status for /etc/letsencrypt/archive/sewan-be.ddns.net/cert1.pem is: OCSPCertStatus.GOOD
2022-04-29 06:54:33,006:DEBUG:certbot._internal.display.obj:Notifying user: Certificate not yet due for renewal
2022-04-29 06:54:33,006:DEBUG:certbot._internal.log:Exiting abnormally:
Traceback (most recent call last):
  File "/usr/local/bin/certbot", line 33, in <module>
    sys.exit(load_entry_point('certbot', 'console_scripts', 'certbot')())
  File "/opt/certbot/src/certbot/certbot/main.py", line 19, in main
    return internal_main.main(cli_args)
  File "/opt/certbot/src/certbot/certbot/_internal/main.py", line 1723, in main
    return config.func(config, plugins)
  File "/opt/certbot/src/certbot/certbot/_internal/main.py", line 1575, in certonly
    should_get_cert, lineage = _find_cert(config, domains, certname)
  File "/opt/certbot/src/certbot/certbot/_internal/main.py", line 357, in _find_cert
    action, lineage = _find_lineage_for_domains_and_certname(config, domains, certname)
  File "/opt/certbot/src/certbot/certbot/_internal/main.py", line 387, in _find_lineage_for_domains_and_certname
    return _find_lineage_for_domains(config, domains)
  File "/opt/certbot/src/certbot/certbot/_internal/main.py", line 332, in _find_lineage_for_domains
    return _handle_identical_cert_request(config, ident_names_cert)
  File "/opt/certbot/src/certbot/certbot/_internal/main.py", line 283, in _handle_identical_cert_request
    response = display_util.menu(question, choices,
  File "/opt/certbot/src/certbot/certbot/display/util.py", line 103, in menu
    return obj.get_display().menu(message, choices, default=default, cli_flag=cli_flag,
  File "/opt/certbot/src/certbot/certbot/_internal/display/obj.py", line 131, in menu
    code, selection = self._get_valid_int_ans(len(choices))
  File "/opt/certbot/src/certbot/certbot/_internal/display/obj.py", line 396, in _get_valid_int_ans
    ans = util.input_with_timeout(input_msg)
  File "/opt/certbot/src/certbot/certbot/_internal/display/util.py", line 68, in input_with_timeout
    raise EOFError
EOFError
2022-04-29 06:54:33,007:ERROR:certbot._internal.log:An unexpected error occurred:
2022-04-29 06:54:33,007:ERROR:certbot._internal.log:EOFError
